Workbook

Sheet DASHBOARD
A1: DASHBOARD GENERAL DE COMPRAS | I1: Pendientes generados en junta | L1: PENDIENTES GENERALES
I2: FALSE | L2: FALSE
A3: Pendientes sin OC | C3: # Proyectos sin OVT-INT | E3: #OC Pendientes de enviar | I3: FALSE | L3: FALSE
A4: =COUNTIF(A10:A1000,"<>") -> 0 | C4: =IFERROR(__xludf.DUMMYFUNCTION("Countunique(filter(G10:G1000,G10:G1000<>""""))"),1.0) -> 1 | I4: FALSE | L4: FALSE
I5: FALSE | L5: FALSE
A6: OC sin Pago | C6: OC sin factura | I6: FALSE | L6: FALSE
I7: FALSE | L7: FALSE
L8: FALSE
A9: Proyecto | B9: Código | C9: Descripción | D9: Cantidad | E9: Proveedor | G9: Proyecto | H9: Descripción | I9: OV-INT | J9: Status de Interempresa
B10: ALT 039 | C10: GALONES DE GEL CONDUCTOR | D10: 2 | E10: PRONAMAC | I10: N/A | J10: TRUE
B11: ALFA-FLEX | C11: Lámpara de examinación | D11: 2 | E11: RIMSA | I11: N/A | J11: TRUE
B12: 137579
B13: 866389 | C13: CENTRAL DE MONITOREO PARA MÚLTIPLES CAMAS (14 MONITORES) | D13: 1 | E13: PHILIPS | I13: N/A | J13: FALSE
B14: 866424 | C14: PIC iX Hardware | D14: 1 | E14: PHILIPS | I14: N/A | J14: FALSE
B15: 866126 | C15: 24" Widescreen LCD Display - touch | D15: 1 | E15: PHILIPS | I15: N/A | J15: FALSE
B16: 866126 | C16: 24" Widescreen LCD Display - touch | D16: 1 | E16: PHILIPS | I16: N/A | J16: FALSE
B17: 867392 | C17: Layer 2 Switch | D17: 1 | E17: PHILIPS | I17: N/A | J17: FALSE
B18: 866389 | C18: CENTRAL DE MONITOREO PARA MÚLTIPLES CAMAS (8 MONITORES) | D18: 1 | E18: PHILIPS | I18: N/A | J18: FALSE
B19: 866424 | C19: PIC iX Hardware | D19: 1 | E19: PHILIPS | I19: N/A | J19: FALSE
B20: 866126 | C20: 24" Widescreen LCD Display - touch | D20: 1 | E20: PHILIPS | I20: N/A | J20: FALSE
B21: 866126 | C21: 24" Widescreen LCD Display - touch | D21: 1 | E21: PHILIPS | I21: N/A | J21: FALSE
B22: 867392 | C22: Layer 2 Switch | D22: 1 | E22: PHILIPS | I22: N/A | J22: FALSE
B23: 21078ST | C23: Skin Temperature Probe, Reusable | D23: 44 | E23: HOSPIINNOVA | I23: N/A | J23: TRUE
B24: M1668A | C24: CBL 5 Lead ECG Trunk AAMI/IEC 2.7m | D24: 22 | E24: PHILIPS | I24: N/A | J24: TRUE
B25: WP010-MX | C25: Wall Mount with adjustable height | D25: 22 | E25: TPX | I25: MPC28349 | J25: FALSE
B26: 31050522 | C26: ELECTRODO DE MONITOREO ECG PACIENTE ADULTO MT200 CAJA CON 10 SOBRES CON 100 PIEZAS | D26: 66 | E26: HOSPIINNOVA | J26: FALSE
B27: 31424743 | C27: ELECTRODOS NEONATAL DE ECG | D27: 2200 | E27: HOSPIINNOVA | J27: FALSE
B28: 21078ST | C28: Skin Temperature Probe, Reusable | D28: 62 | E28: HOSPIINNOVA | I28: N/A | J28: TRUE
B29: M1668A | C29: CBL 5 Lead ECG Trunk AAMI/IEC 2.7m | D29: 31 | E29: PHILIPS | I29: N/A | J29: TRUE
B30: RP050 | C30: Rolling Stand--For Patient Monitor | D30: 31 | E30: TPX | I30: MPC28349 | J30: FALSE
B31: PL-MX | C31: BASE PARA MONITOR PHILIPS MX | D31: 31 | E31: TPX | J31: FALSE
B32: 31424743 | C32: ELECTRODOS NEONATAL | D32: 3100 | E32: HOSPIINNOVA | J32: FALSE
B33: 31050522 | C33: ELECTRODO DE MONITOREO ECG PACIENTE ADULTO MT200 CAJA CON 10 SOBRES CON 100 PIEZAS | D33: 93 | E33: HOSPIINNOVA | J33: FALSE
B34: 21078ST | C34: Skin Temperature Probe, Reusable | D34: 30 | E34: HOSPIINNOVA | I34: N/A | J34: TRUE
B35: M1668A | C35: CBL 5 Lead ECG Trunk AAMI/IEC 2.7m | D35: 15 | E35: PHILIPS | I35: N/A | J35: TRUE
B36: RP050 | C36: Rolling Stand--For Patient Monitor | D36: 15 | E36: TPX | I36: MPC28349 | J36: FALSE
B37: PL-MX | C37: BASE PARA MONITOR PHILIPS MX | D37: 15 | E37: TPX | J37: FALSE
B38: 31424743 | C38: ELECTRODOS NEONATAL | D38: 1500 | E38: HOSPIINNOVA | J38: FALSE
B39: 31050522 | C39: ELECTRODO DE MONITOREO ECG PACIENTE ADULTO MT200 CAJA CON 10 SOBRES CON 100 PIEZAS | D39: 45 | E39: HOSPIINNOVA | J39: FALSE
B40: 21078ST | C40: Skin Temperature Probe, Reusable | D40: 2 | E40: HOSPIINNOVA | I40: N/A | J40: TRUE
...

Sheet CMR
A1: #Orden de compra | B1: Código | C1: Descripción | D1: Cantidad | E1: Referencia
A2: MAN01120 | B2: MA-1164-2 | C2: CART - TOP CONTROL PANEL FRU KIT ASSEMBLY | D2: 1 | E2: GARANTÍA | SD-UK01007876 / SD-UK01007881
A3: MAN01120 | B3: MA-1182-1 | C3: Haptic Linkage FRU Kit Assembly | D3: 2 | E3: GARANTÍA | SD-UK01007876 / SD-UK01007881
A4: MAN01120 | B4: EA-0816-A | C4: USB 2.0 left angle A to micro-B cable 762mm | D4: 1 | E4: GARANTÍA | SD-UK01007876 / SD-UK01007881
A5: MAN01120 | B5: MA-1173-1 | C5: Console Top Deck Electronics FRU Kit Assembly | D5: 1 | E5: GARANTÍA | SD-UK01007876 / SD-UK01007881
A6: MAN01115 | B6: 10400 | C6: Instrumento Gancho monopolar Versius | D6: 1 | E6: MATERIAL PARA ENTRENAMIENTO
A7: MAN01115 | B7: 10200 | C7: Pinzas de agarre bipolares Maryland Versius. | D7: 2 | E7: MATERIAL PARA ENTRENAMIENTO
A8: MAN01115 | B8: 10500 | C8: Curved Scissors | D8: 1 | E8: MATERIAL PARA ENTRENAMIENTO
A9: MAN01115 | B9: 10600 | C9: Tijeras curvas monopolares Versius. | D9: 2 | E9: MATERIAL PARA ENTRENAMIENTO
A10: MAN01115 | B10: 10300 | C10: Pinzas de agarre Grasper fenestradas Versius. | D10: 1 | E10: MATERIAL PARA ENTRENAMIENTO
A11: MAN01115 | B11: 10100 | C11: Instrumento Portaagujas Versius | D11: 1 | E11: MATERIAL PARA ENTRENAMIENTO
A12: MAN01115 | B12: 20901 | C12: Tapa aislante de cabeza de cubierta | D12: 1 | E12: MATERIAL PARA ENTRENAMIENTO
A13: MAN01115 | B13: 20101 | C13: Cubierta Versius para unidad de instrumento (Corta) | D13: 1 | E13: MATERIAL PARA ENTRENAMIENTO
A14: MAN01115 | B14: 20301 | C14: Cubierta Versius para unidad de instrumento (Larga) | D14: 1 | E14: MATERIAL PARA ENTRENAMIENTO
A15: MAN01115 | B15: 10002 | C15: Paquete de accesorios con forro aislante flexible | D15: 1 | E15: MATERIAL PARA ENTRENAMIENTO
A16: MAN01115 | B16: 20401 | C16: Cubierta Versius para unidad de visualización (Larga) | D16: 1 | E16: MATERIAL PARA ENTRENAMIENTO
A17: MAN01115 | B17: 20501 | C17: Cubierta Versius para cabeza de Cámara | D17: 1 | E17: MATERIAL PARA ENTRENAMIENTO
A18: MAN01114 | B18: MA-1162-1 | C18: Arm Backup Battery FRU Kit Assembly | D18: 3 | E18: GARANTÍA | MA-1162-1
A19: MAN01111 | B19: 10600-T | C19: 10600-T | D19: 6 | E19: STOCK / SERVICIO
A20: MAN01110 | B20: 10100 | C20: Instrumento Portaagujas Versius | D20: 21 | E20: STOCK
A21: MAN01110 | B21: 10200 | C21: Pinzas de agarre bipolares Maryland Versius. | D21: 20 | E21: STOCK
A22: MAN01110 | B22: 10300 | C22: Pinzas de agarre Grasper fenestradas Versius. | D22: 17 | E22: STOCK
A23: MAN01110 | B23: 10400 | C23: Instrumento Gancho monopolar Versius | D23: 33 | E23: STOCK
A24: MAN01110 | B24: 10600 | C24: Tijeras curvas monopolares Versius. | D24: 21 | E24: STOCK
A25: MAN01110 | B25: 20101 | C25: Cubierta Versius para unidad de instrumento (Corta) | D25: 75 | E25: STOCK
A26: MAN01110 | B26: 20201 | C26: Cubierta Versius para unidad de visualización (Corta) | D26: 25 | E26: STOCK
A27: MAN01110 | B27: 20501 | C27: Cubierta Versius para cabeza de Cámara | D27: 11 | E27: STOCK
A28: MAN01110 | B28: 20901 | C28: Tapa aislante de cabeza de cubierta | D28: 5 | E28: STOCK
A29: MAN01110 | B29: 10002 | C29: Paquete de accesorios con forro aislante flexible | D29: 15 | E29: STOCK
A30: MAN01004 | B30: V-SS-1000 | C30: VERSIUS Surgeon Console | D30: 2 | E30: IMSS Bienestar | N-62-2026
A31: MAN01004 | B31: V-SS-2000 | C31: VERSIUS Instrument Bedside Unit | D31: 6 | E31: IMSS Bienestar | N-62-2026
A32: MAN01004 | B32: V-SS-3000 | C32: VERSIUS Visualisation Bedside Unit | D32: 2 | E32: IMSS Bienestar | N-62-2026
A33: MAN01004 | B33: 90900 | C33: Versius Camera Head | D33: 4 | E33: IMSS Bienestar | N-62-2026
A34: MAN01004 | B34: 90907 | C34: Versius 30 Degree Endoscope | D34: 4 | E34: IMSS Bienestar | N-62-2026
A35: MAN01004 | B35: 90908 | C35: Versius 0 Degree Endoscope | D35: 4 | E35: IMSS Bienestar | N-62-2026
A36: MAN01004 | B36: 90903 | C36: Light Cable (3.5m) | D36: 8 | E36: IMSS Bienestar | N-62-2026
A37: MAN01004 | B37: 90904 | C37: Light Source | D37: 2 | E37: IMSS Bienestar | N-62-2026
A38: MAN01004 | B38: 90200/10 | C38: Auxiliary Screen Cable -Long | D38: 4 | E38: IMSS Bienestar | N-62-2026
A39: MAN01004 | B39: 90200/5 | C39: Auxiliary Screen Cable -Short | D39: 4 | E39: IMSS Bienestar | N-62-2026
A40: MAN01004 | B40: 90100/10 | C40: Video Feed Cable-Long | D40: 4 | E40: IMSS Bienestar | N-62-2026
...

Sheet B2B
A1: VENTAS
A2: Modelo | B2: Descripción | C2: Total | F2: DESCRIPCIÓN | G2: CÓDIGO | H2: PROVEEDOR | I2: STOCK | J2: PRESENTACIÓN
A3: 867246 | B3: Avalon US Transducer | C3: 2 | F3: Adult NIBP Air Hose 3.0m | G3: 989803209771 | H3: PHILIPS | I3: 32 | J3: pz
A4: 867248 | B4: Avalon TOCO MP Transducer | C4: 1 | F4: Airway Adapter-Reusable-Adult/Pediatric | G4: 989803206591 | H4: PHILIPS | I4: 17 | J4: pz
A5: 867249 | B5: Transductor Avalon TOCO+ | C5: 1 | F5: BATTERY 10.8V 6Ah LiIon | G5: M4605A | H5: PHILIPS | I5: 0 | J5: pz
A6: 989803136891 | B6: Recording Paper | C6: 4 | F6: CBL 10 Lead ECG Trunk AAMI/IEC 2m | G6: M1663A | H6: PHILIPS | I6: 25 | J6: pz
A7: 989803145061 | B7: CBL 5 Lead ECG Trunk AAMI/IEC 2.7m (M1668A) | C7: 106 | F7: CBL 3 Lead ECG Trunk AAMI/IEC 2.7m | G7: M1669A | H7: PHILIPS | I7: 415 | J7: pz
A8: 989803161991 | B8: Quick Connect SpO2 Probe MRI | C8: 1 | F8: CBL 5 Lead ECG Trunk AAMI/IEC 2.7m | G8: M1668A | H8: PHILIPS | I8: 21 | J8: pz
A9: 989803166581 | B9: Quick Connect SpO2 Grip Neo 20/box | C9: 1 | F9: CBL 5 Leadset Grabber AAMI ICU | G9: M1968A | H9: PHILIPS | I9: 33 | J9: pz
A10: 989803167551 | B10: Neonatal Soft Single-Patient NIBP Cuffs | C10: 6 | F10: CBL 5 Leadset Grabber Chest AAMI ICU | G10: M1976A | H10: PHILIPS | I10: 1 | J10: pz
A11: 989803169491 | B11: Battery MRI 14.8V 5.08 AH UL | C11: 1 | F11: CBL 5 Leadset Snap AAMI ICU | G11: M1644A | H11: PHILIPS | I11: 5 | J11: pz
A12: 989803170121 | B12: Avanced filter ECG cable | C12: 1 | F12: CBL Cardiac Output Cable | G12: M1642A | H12: PHILIPS | I12: 27 | J12: pz
A13: 989803182621 | B13: NiBP Cuff Single Lumen Pediatric | C13: 1 | F13: CBL SpO2 Extension Cable 2m | G13: M1941A | H13: PHILIPS | I13: 22 | J13: pz
A14: 989803182641 | B14: NiBP Cuff Single Lumen Adult | C14: 1 | F14: CBL Unshielded 3 Ld Miniclip AAMI 0.7m | G14: M1624A | H14: PHILIPS | I14: 9 | J14: pz
A15: 989803190381 | B15: Efficia 50mm Chem Therm Paper No Lines | C15: 15 | F15: Co-Set(TM) Injectate Temp Probe - 7'9 | G15: 23001A | H15: PHILIPS | I15: 0 | J15: pz
A16: 989803193731 | B16: Expression MR ECG Leads AAMI Standard Philips | C16: 4 | F16: Easy Care Cuff 1 Hose Adult (1) | G16: M4555B | H16: PHILIPS | I16: 48 | J16: pz
... A18: 989803203561 | B18: Sensor de temperatura Esofágico / Rectal, 12 FR Philips | C18: 11 | F18: Ice Bath Temperature Probe | G18: 23002A | H18: PHILIPS | I18: 0 | J18: pz
A19: 989803205901 | B19: Sensor SpO2 Reusable Adult Clip Sensor M1196A | C19: 20 | F19: IntelliVue Capnography Extension | G19: 867040 | H19: PHILIPS | I19: 5 | J19: pz
A20: 989803209771 | B20: Adult NIBP Air Hose 3.0m | C20: 30 | F20: Mainstream Sensor | G20: M2501A | H20: PHILIPS | I20: 78 | J20: pz
A21: 989803210521 | B21: BATERIA 3S3P LiIon 10.7V 7.1Ah | C21: 11 | F21: Neonatal NIBP Air Hose 3.0m | G21: 989803209751 | H21: PHILIPS | I21: 147 | J21: pz
A22: M1191B | B22: Reusable Adult SpO2 Sensor | C22: 12 | F22: Neonatal Soft Single-Patient Cuff Size#1 | G22: M1866S | H22: PHILIPS | I22: 796 | J22: pz
A23: M1191BL | B23: Reusable Adult SpO2 Sensor | C23: 18 | F23: Neonatal Soft Single-Patient Cuff Size#2 | G23: M1868S | H23: PHILIPS | I23: 1801 | J23: pz
A24: M1571A | B24: Comfort Care Cuff Infant | C24: 5 | F24: Neonatal Soft Single-Patient Cuff Size#3 | G24: M1870S | H24: PHILIPS | I24: 5556 | J24: pz
A25: M1573A | B25: Reusable NIBP Comfort Cuff/small adult | C25: 2 | F25: Reusable Adult SpO2 Sensor | G25: M1191B | H25: PHILIPS | I25: 414 | J25: pz
A26: M1574A | B26: Reusable NIBP Comfort Cuff/ adult | C26: 10 | F26: SPO2 Reus Neo Hnd-Ft Wrap Sensor M1193A | G26: 989803205881 | H26: PHILIPS | I26: 4 | J26: pz
A27: M1576A | B27: Reusable NIBP Comfort Cuff/thigh | C27: 1 | F27: SPO2 Reus Ped-Adult Glove Sensor M1192A | G27: 989803205871 | H27: PHILIPS | I27: 33 | J27: pz
A28: M1599B | B28: Adult Pressure Interconnect Cable 3.0m | C28: 100 | F28: Temperature Parameter Module | G28: M1029A | H28: PHILIPS | I28: 84 | J28: pz
A29: M1642A | B29: CBL Cardiac Output Cable | C29: 9 | F29: Thermal Array Recorder Module | G29: M1116C | H29: PHILIPS | I29: 0 | J29: pz
A30: M1644A | B30: CBL 5 Leadset Snap AAMI ICU | C30: 83
A31: M1663A | B31: CBL 10 Lead ECG Trunk AAMI/IEC 2m | C31: 7
A32: M1669A | B32: CBL 3 Lead ECG Trunk AAMI/IEC 2.7m | C32: 15
A33: M1671A | B33: CBL 3 Leadset Grabber AAMI ICU | C33: 0
A34: M1673A | B34: CBL 3 Leadset Snap AAMI ICU | C34: 10
A35: M1870S | B35: Neonatal Soft Single-Patient Cuff Size#3 | C35: 15
A36: M1910A | B36: Fetal monitoring recording pape | C36: 215
A37: M1941A | B37: CBL SpO2 Extension Cable 2m | C37: 106
A38: M1943AL | B38: Sp02 8-pin D-sub Adapter cable 3m (8pin) | C38: 2
A39: M1943NL | B39: Sp02 8-pin D-sub Adapter cbl (8pin) Oxi | C39: 5
A40: M1968A | B40: CBL 5 Leadset Grabber AAMI ICU | C40: 13
A41: M2267A | B41: Calibration Regulator | C41: 1
...

Sheet IMSS BIENESTAR QUINTANA ROO IM-
A1: PEDIDO | B1: PARTIDA | C1: DESCRIPCIÓN | D1: CANTIDAD | E1: UDM | F1: MARCA | G1: MODELO | H1: CÓDIGO | I1: PROVEEDOR | J1: Empresa que vende | K1: COSTO | L1: MONEDA COSTO | M1: EMPRESA QUE COMPRA | N1: OC | O1: B2B | P1: OBSERVACIONES | Q1: ESTATUS | R1: OV-INT | S1: Status de Interempresa | T1: OC-INT | U1: Status de Interempresa | V1: FACTURA CIEGA | W1: PEDIMENTO | X1: CARTA DE FABRICACION
A2: MAN12662 | B2: 8 | C2: Báscula electrónica | D2: 1 | E2: PIEZA | F2: SECA | G2: 354m | H2: seca 354 | I2: SECA | J2: Manprec | K2: 3900 | L2: MXN | M2: Manprec | N2: Stock | O2: FALSE | P2: Se recupera equipo en OC MAN00863 | Q2: ALMACEN 11 | R2: N/A | S2: TRUE | T2: N/A | U2: TRUE | V2: COMPARTIDO | W2: COMPARTIDO | X2: COMPARTIDO
A3: MAN12662 | B3: 9 | C3: Cama camilla radiotransparente | D3: 1 | E3: PIEZA | F3: GIVAS | G3: BT1205 | H3: BT1205 | I3: GIVAS | J3: Manprec | L3: EURO | M3: ITH | N3: Stock | O3: FALSE | Q3: STOCK | R3: ITH00917 | S3: TRUE | T3: MAN00890 | U3: TRUE | V3: COMPARTIDO | W3: COMPARTIDO | X3: COMPARTIDO
A4: MAN12662 | B4: 15 | C4: Electrocardiógrafo multicanal con interpretación. | D4: 1 | E4: PIEZA | F4: SCHILLER | G4: CARDIOVIT AT-102 G2 | H4: 0A.108000 | I4: SCHILLER | J4: Manprec | K4: 65190 | L4: USD | M4: ITH | N4: Stock | O4: TRUE | Q4: ALMACEN 11 | R4: ITH00917 | S4: TRUE | T4: MAN00890 | U4: TRUE | V4: COMPARTIDO | W4: COMPARTIDO | X4: COMPARTIDO
B5: 15 | C5: SCHILLER Culprit Coronary Artery Algorithm Software (CCAA) AT-102 G2 Identifies the site of obstruction in the coronary artery and | D5: 1 | E5: PIEZA | F5: Schiller | H5: 5.108004 | I5: SCHILLER | J5: Manprec | K5: 816 | L5: USD | M5: ITH | N5: ITH00171 | O5: FALSE | Q5: ALMACEN 11 | R5: ITH00917 | S5: TRUE | T5: MAN00890 | U5: TRUE
B6: 15 | C6: Carro de transporte | D6: 1 | E6: PIEZA | F6: TPX | H6: RP050-6 | I6: TPX | J6: Manprec | K6: 127.5 | L6: USD | M6: MPC | N6: Stock | O6: FALSE | Q6: ALMACEN 11 | R6: MPC25190 | S6: TRUE | T6: MAN00871 | U6: TRUE
B7: 15 | C7: Gel 250 ML | D7: 2 | E7: PIEZA | F7: Ultrasonic | H7: ALT 040 | I7: PRONAMAC | J7: Manprec | K7: 55.86 | L7: MXN | M7: MPC | N7: Stock | O7: FALSE | Q7: ALMACEN 11 | R7: MPC25190 | S7: TRUE | T7: MAN00871 | U7: TRUE
B8: 15 | C8: Thermal chart paper AT-102, AT-102 plus, AT-102 G2, | D8: 3 | E8: PIEZA | F8: Schiller | H8: 2.157050 | I8: SCHILLER | J8: Manprec | K8: 18 | L8: USD | M8: ITH | N8: ITH00171 | O8: TRUE | Q8: ALMACEN 11 | R8: ITH00917 | S8: TRUE | T8: MAN00890 | U8: TRUE
B9: 15 | C9: Electrodos desechables Bolsa de 100 pz | D9: 5 | E9: PIEZA | F9: Cardinal | H9: 31050522 | I9: HOSPIINNOVA | J9: Manprec | K9: 250 | L9: MXN | M9: Manprec | N9: Stock | O9: FALSE | Q9: ALMACEN 11 | R9: N/A | S9: TRUE | T9: N/A | U9: TRUE
B10: 15 | C10: Li-ion Battery AT-102 G2 (caution AT-102 G2 must | D10: 1 | E10: PIEZA | F10: Schiller | H10: 4.350066A | I10: SCHILLER | J10: Manprec | K10: 368 | L10: USD | M10: ITH | N10: ITH00171 | O10: FALSE | Q10: ALMACEN 11 | R10: ITH00917 | S10: TRUE | T10: MAN00890 | U10: TRUE
A11: MAN12662 | B11: 50 | C11: Unidad radiológica portatil digital | D11: 1 | E11: PIEZA | F11: PHILIPS | G11: MOBILEDIAGNOST WDR | H11: WDR40PMX | I11: PHILIPS | J11: Manprec | K11: =95000+6000 -> 101000 | L11: USD | M11: Manprec | N11: MAN00865 | O11: FALSE | Q11: CON PHILIPS | R11: N/A | S11: TRUE | T11: N/A | U11: TRUE | V11: COMPARTIDO | W11: COMPARTIDO | X11: SOLICITADO
C12: Mandil plomado | D12: 1 | E12: PIEZA | H12: JDS536 | I12: NAFARRATE | J12: Manprec | K12: 2931.6 | L12: MXN | M12: Manprec | N12: MAN00862 | O12: FALSE | Q12: ALMACEN 11 | R12: N/A | S12: TRUE | T12: N/A | U12: TRUE
C13: Goggles de plomo | D13: 1 | E13: PIEZA | H13: JD53 | I13: NAFARRATE | J13: Manprec | K13: 2981 | L13: MXN | M13: Manprec | N13: MAN00862 | O13: FALSE | Q13: ALMACEN 11 | R13: N/A | S13: TRUE | T13: N/A | U13: TRUE
C14: Protector de tiroides de plomo | D14: 1 | E14: PIEZA | H14: JD611NSL | I14: NAFARRATE | J14: Manprec | K14: 543.4 | L14: MXN | M14: Manprec | N14: Stock | O14: FALSE | Q14: ALMACEN 11 | R14: MPC25190 | S14: TRUE | T14: MAN00871 | U14: TRUE
C15: Protector de gonadas de plomo | D15: 1 | E15: PIEZA | H15: JD806L | I15: NAFARRATE | J15: Manprec | K15: 720.2 | L15: MXN | M15: Manprec | N15: Stock | O15: FALSE | Q15: ALMACEN 11 | R15: MPC25190 | S15: TRUE | T15: MAN00871 | U15: TRUE
C16: Guantes de plomo | D16: 1 | E16: PIEZA | H16: JD100V-DKB | I16: NAFARRATE | J16: Manprec | K16: 3731.6 | L16: MXN | M16: Manprec | N16: Stock | O16: FALSE | Q16: ALMACEN 11 | R16: MPC25190 | S16: TRUE | T16: MAN00871 | U16: TRUE
C17: DVD's Torre de 100 pz | D17: 2 | E17: C/100 | H17: B00O0IDJT2 | I17: AMAZON | J17: Manprec | K17: 382.76 | L17: MXN | M17: MPC | N17: MPC03113 | O17: FALSE | Q17: ALMACEN 11 | R17: MPC25190 | S17: TRUE | T17: MAN00871 | U17: TRUE
C18: Regulador supresor de picos 3KVA | D18: 1 | E18: PIEZA | H18: LAN-15 | I18: MERCADOLIBRE | J18: Manprec | K18: 12753.88 | L18: MXN | M18: MPC | N18: MPC03823 | O18: FALSE | Q18: SE COMPRO POR MERCADOLIBRE | R18: MPC25190 | S18: TRUE | T18: MAN00871 | U18: TRUE
A19: MAN12662 | B19: 71 | C19: REFRIGERADOR VERTICAL PARA LABORATORIO CAP. 20 PIES CUBICOS | D19: 1 | E19: EQUIPO | F19: REFRIMED | G19: RVCCDV-20 | H19: RVCCDV-20 | I19: REFRIMED | J19: Manprec | K19: 62000 | L19: MXN | M19: Manprec | N19: MAN00861 | O19: FALSE | Q19: ENTREGADA | R19: N/A | S19: TRUE | T19: N/A | U19: TRUE | V19: COMPARTIDO | W19: N/A | X19: COMPARTIDO

Sheet SSCDMX- SRMAS-JUDCCM.ADQ.150-25
A1: PEDIDO | B1: PARTIDA | C1: DESCRIPCIÓN | D1: CANTIDAD | E1: UDM | F1: MARCA | G1: MODELO | H1: CÓDIGO | I1: PROVEEDOR | J1: Empresa que vende | K1: COSTO | L1: MONEDA COSTO | M1: EMPRESA QUE COMPRA | N1: OC | O1: B2B | P1: OBSERVACIONES | Q1: ESTATUS | R1: OV-INT | S1: Status de Interempresa | T1: OC-INT | U1: Status de Interempresa
A2: MPC27121 / MPC26257 | B2: 1 | C2: Densitómetro oseo | D2: 2 | E2: PZ | F2: Hologic | G2: Discovery Wii | H2: Discovery Wii | I2: SMH | J2: MPC | K2: 52000 | L2: USD | M2: CEO | N2: CEO00131 | O2: FALSE | P2: - | Q2: ENTREGADO DIRECTO | R2: CEO00273 | S2: TRUE | T2: MPC04010 | U2: TRUE
C3: UPS 2KVA | D3: 2 | E3: PZ | J3: MPC | K3: 0 | L3: USD | M3: CEO | N3: CEO00131 | O3: FALSE | P3: Parte del equipo | Q3: ENTREGADO DIRECTO | R3: CEO00273 | S3: TRUE | T3: MPC04010 | U3: TRUE
C4: Impresora | D4: 2 | E4: PZ | J4: MPC | K4: 0 | L4: USD | M4: CEO | N4: CEO00131 | O4: FALSE | P4: Parte del equipo | Q4: ENTREGADO DIRECTO | R4: CEO00273 | S4: TRUE | T4: MPC04010 | U4: TRUE
C5: Cartucho de tinta o toner para impresoa | D5: 2 | E5: PZ | J5: MPC | K5: 0 | L5: USD | M5: CEO | N5: CEO00131 | O5: FALSE | P5: Parte del equipo | Q5: ENTREGADO DIRECTO | R5: CEO00273 | S5: TRUE | T5: MPC04010 | U5: TRUE
C6: CPU con monitor. | D6: 2 | E6: PZ | J6: MPC | K6: 0 | L6: USD | M6: CEO | N6: CEO00131 | O6: FALSE | P6: Parte del equipo | Q6: ENTREGADO DIRECTO | R6: CEO00273 | S6: TRUE | T6: MPC04010 | U6: TRUE
C7: paquete de 500 hojas | D7: 2 | E7: PZ | J7: MPC | L7: MXN | M7: MPC | N7: Stock | O7: FALSE | P7: Se enviará sin salida | Q7: EN ALMACEN 11 | S7: FALSE | U7: FALSE
B8: 2 | C8: Congelador para vacunas | D8: 2 | E8: PZ | F8: Refrimed | G8: CH-7 | H8: CH-7 | I8: REFRIMED | J8: MPC | K8: 28675.5 | L8: MXN | M8: MPC | N8: MPC03814 | O8: FALSE | P8: Se cancelan para este proyecto | Q8: CANCELADO | R8: N/A | S8: TRUE | T8: N/A | U8: TRUE
B9: 8 | C9: Ultrasonografo | D9: 2 | E9: PZ | F9: Philips | G9: Affiniti 30 | I9: PHILIPS | J9: MPC | L9: USD | M9: Manprec | O9: FALSE | P9: - | Q9: ENTREGADO DIRECTO | R9: MAN12887 | S9: TRUE | T9: MPC03977 | U9: TRUE
C10: UPS EN LÍNEA DE DOBLE CONVERSIÓN, AUTOMÁTICO QUE INCLUYA SUPRESOR DE PICOS. | D10: 2 | E10: PZ | H10: PA MG+15-2200-UN | I10: ALTERNATIVA | J10: MPC | K10: 3884 | L10: MXN | M10: Gamit | N10: GAM00042 | O10: FALSE | P10: - | Q10: EN ALMACEN 11 | R10: GAM00148 | S10: TRUE | T10: MPC04024 | U10: TRUE
C11: CD'S | D11: 20 | E11: PZ | J11: MPC | M11: MPC | O11: FALSE | P11: - | Q11: EN ALMACEN 11 | R11: N/A | S11: TRUE | T11: N/A | U11: TRUE
C12: CAJAS DE PELÍCULA PARA IMPRESORA | D12: 2 | E12: PZ | J12: MPC | M12: MPC | O12: FALSE | P12: - | Q12: CANCELADO | R12: N/A | S12: TRUE | T12: N/A | U12: TRUE
C13: GALONES DE GEL CONDUCTOR | D13: 2 | E13: PZ | H13: ALT 039 | I13: PRONAMAC | J13: MPC | M13: MPC | O13: FALSE | P13: - | Q13: EN ALMACEN 11 | R13: N/A | S13: TRUE | T13: N/A | U13: TRUE
B14: 10 | C14: Lámpara de examinación | D14: 2 | E14: PZ | F14: Rimsa | G14: AlfaFlex | H14: ALFA-FLEX | I14: RIMSA | J14: MPC | K14: 184.8 | L14: EURO | M14: MPC | O14: FALSE | P14: - | Q14: EN ALMACEN 11 | R14: N/A | S14: TRUE | T14: N/A | U14: TRUE
B15: 11 | C15: Estatoscopio de capsula doble | D15: 25 | E15: PZ | F15: Welch Allyn | G15: Spectrum | H15: WA5079-135 | I15: NAFARRATE | J15: MPC | K15: 1601.8 | L15: MXN | M15: MPC | N15: MPC03818 | O15: FALSE | P15: - | Q15: EN ALMACEN 11 | R15: N/A | S15: TRUE | T15: N/A | U15: TRUE
B16: 12 | C16: Estuche de diagnostico | D16: 10 | E16: PZ | F16: Welch Allyn | G16: 97200-CL | H16: WA97200-CL | I16: NAFARRATE | J16: MPC | K16: 7373.8 | L16: MXN | M16: MPC | N16: MPC03818 | O16: FALSE | P16: - | Q16: EN ALMACEN 11 | R16: N/A | S16: TRUE | T16: N/A | U16: TRUE
C17: ESPECULO REUSABLE P/OTOSCOPIO JUEGO CON 4 | D17: 10 | E17: PZ | F17: Welch Allyn | H17: WA24400-U | I17: NAFARRATE | J17: MPC | K17: 208.8 | L17: MXN | M17: MPC | N17: MPC03818 | O17: FALSE | P17: - | Q17: EN ALMACEN 11 | R17: N/A | S17: TRUE | T17: N/A | U17: TRUE
C18: Porta depresor de lengua 3.5 halógeno | D18: 10 | E18: PZ | F18: Welch Allyn | H18: WA28100 | I18: NAFARRATE | J18: MPC | K18: 4262.4 | L18: MXN | M18: MPC | N18: MPC03818 | O18: FALSE | P18: - | Q18: EN ALMACEN 11 | R18: N/A | S18: TRUE | T18: N/A | U18: TRUE
B19: 14 | C19: Refrigerador de laboratorio | D19: 1 | E19: PZ | F19: Refrimed | G19: RVCCDV-2 | H19: RVCCDV-2 | I19: REFRIMED | J19: MPC | K19: 23775.3 | L19: MXN | M19: MPC | N19: MPC03814 | O19: FALSE | P19: Se cancelan para este proyecto | Q19: CANCELADO | R19: N/A | S19: TRUE | T19: N/A | U19: TRUE
B20: 15 | C20: Refrigerador para vacunas | D20: 1 | E20: PZ | F20: Refrimed | G20: RVASCV-17 | H20: RVASCV-17 | I20: REFRIMED | J20: MPC | K20: 61978.6 | L20: MXN | M20: MPC | N20: MPC03814 | O20: FALSE | P20: Se cancelan para este proyecto | Q20: CANCELADO | R20: N/A | S20: TRUE | T20: N/A | U20: TRUE
B21: 18 | C21: Analizador de composición corporal | D21: 2 | E21: PZ | F21: Seca | G21: 525 | H21: Seca 525 | I21: SECA | J21: MPC | K21: =141631.88+7200+7200 -> 156031.88 | L21: MXN | M21: Manprec | N21: MAN00894 | O21: FALSE | P21: - | Q21: EN ALMACEN 11 | R21: MAN12887 | S21: TRUE | T21: MPC03977 | U21: TRUE
C22: LAPTOP WINDOWS 10 PRO 64, 4 GB RAM, DISCO DURO 1 TB, PUERTOS USB, CONECTIVIDAD LAN/ETHERNET, INTERFAZ CONEXIÓN IMPRESORA | D22: 2 | E22: PZ | F22: ThinkPad E14 Gen 5 | H22: B0G8SYBGST | I22: AMAZON | J22: MPC | K22: 7757.76 | L22: MXN | M22: MPC | N22: MPC03994 | O22: FALSE | P22: - | Q22: EN ALMACEN 11 | R22: N/A | S22: TRUE | T22: N/A | U22: TRUE

Sheet SEMAR MAZATLAN
A1: PEDIDO | B1: PARTIDA | C1: DESCRIPCIÓN | D1: CANTIDAD | E1: UDM | F1: MARCA | G1: MODELO | H1: CÓDIGO | I1: PROVEEDOR | J1: Empresa que vende | K1: COSTO | L1: MONEDA COSTO | M1: EMPRESA QUE COMPRA | N1: OC | O1: B2B | P1: OBSERVACIONES | Q1: ESTATUS | R1: OV-INT | S1: Status de Interempresa | T1: OC-INT | U1: Status de Interempresa
A2: ITH00948 | B2: 1 | C2: Unidad De Electrocirugía De Uso General | D2: 1 | E2: PZ | F2: WEM | G2: SS501SX | H2: 06725 | I2: METRONIC | J2: ITH | K2: 119949 | L2: MXN | M2: MPC | N2: MPC04136 | O2: FALSE | Q2: EN ALMACEN 11 | R2: MPC27570 | S2: TRUE | T2: ITH00190 | U2: TRUE
A3: ITH00948 | C3: WEM - CARRO PORTA EQUIPO | D3: 1 | E3: PZ | H3: 04718 | I3: METRONIC | J3: ITH | K3: 16913 | L3: MXN | M3: MPC | N3: MPC04136 | O3: FALSE | Q3: EN ALMACEN 11 | R3: MPC27570 | S3: TRUE | T3: ITH00190 | U3: TRUE
A4: ITH00948 | C4: WEM SS501SX/SS601MCA - PEDAL MONOPOLAR | D4: 1 | E4: PZ | H4: 06523 | I4: METRONIC | J4: ITH | K4: 13531 | L4: MXN | M4: MPC | N4: MPC04136 | O4: FALSE | Q4: EN ALMACEN 11 | R4: MPC27570 | S4: TRUE | T4: ITH00190 | U4: TRUE
A5: ITH00948 | C5: WEM SS501SX - PEDAL BIPOLAR SIMPLE | D5: 1 | E5: PZ | H5: 09922 | I5: METRONIC | J5: ITH | K5: 7881 | L5: MXN | M5: MPC | N5: MPC04136 | O5: FALSE | Q5: EN ALMACEN 11 | R5: MPC27570 | S5: TRUE | T5: ITH00190 | U5: TRUE
A6: ITH00948 | C6: LÁPIZ RELIANT BUTTON SWITCH Y HOLSTER (3M) | D6: 1 | E6: C/50 | H6: E2516 | I6: METRONIC | J6: ITH | K6: 11800 | L6: MXN | M6: MPC | N6: STOCK | O6: FALSE | Q6: EN ALMACEN 11 | R6: MPC27570 | S6: TRUE | T6: ITH00190 | U6: TRUE
A7: ITH00948 | C7: PLACA REM POLYHESIVE II CON CABLE ADULTO | D7: 1 | E7: C/50 | H7: E7507 | I7: METRONIC | J7: ITH | K7: 5040 | L7: MXN | M7: MPC | N7: MPC04136 | O7: FALSE | Q7: EN ALMACEN 11 | R7: MPC27570 | S7: TRUE | T7: ITH00190 | U7: TRUE
A8: ITH00948 | C8: FORCEPS BIPOLARES - CABLE REUSABLE | D8: 1 | E8: PZ | H8: E0020V | I8: METRONIC | J8: ITH | K8: 4960 | L8: MXN | M8: MPC | N8: STOCK | O8: FALSE | Q8: EN ALMACEN 11 | R8: MPC27570 | S8: TRUE | T8: ITH00190 | U8: TRUE
A9: ITH00948 | C9: FORCEPS BIPOLARES - BAYONETA SCOVILLE 19.7CM - 1.5MM | D9: 1 | E9: PZ | H9: E4051-CT | I9: METRONIC | J9: ITH | K9: 9413 | L9: MXN | M9: MPC | N9: MPC04136 | O9: FALSE | Q9: EN ALMACEN 11 | R9: MPC27570 | S9: TRUE | T9: ITH00190 | U9: TRUE
A10: ITH00948 | C10: FORCEPS BIPOLARES - RECTOS CUSHING 17.8CM - 1.5MM | D10: 1 | E10: PZ | H10: E4052-CT | I10: METRONIC | J10: ITH | K10: 8806 | L10: MXN | M10: MPC | N10: STOCK | O10: FALSE | Q10: EN ALMACEN 11 | R10: MPC27570 | S10: TRUE | T10: ITH00190 | U10: TRUE
A11: ITH00948 | C11: ELECTRODO DE TUNGTENO MICRO AGUJA RECTA 2.13" (5.4CM) | D11: 10 | E11: PZ | H11: E1651 | J11: ITH | K11: 1112.5 | L11: MXN | M11: Manprec | N11: MAN00943 | O11: FALSE | P11: GENERICO | Q11: EN ALMACEN 11 | R11: MAN13176 | S11: TRUE | T11: ITH00189 | U11: TRUE
A12: ITH00948 | C12: ELECTRODO DE TUNGTENO MICRO AGUJA ANGULADO 2.13" (2.13CM) 1CM DE LA PUNTA | D12: 10 | E12: PZ | H12: E1551G | I12: METRONIC | J12: ITH | K12: =7814/150 -> 52.093333 | L12: MXN | M12: MPC | N12: STOCK | O12: FALSE | Q12: EN ALMACEN 11 | R12: MPC27570 | S12: TRUE | T12: ITH00190 | U12: TRUE
A13: ITH00948 | C13: LLETZ BOLA 5MM | D13: 10 | E13: PZ | H13: E1564 | J13: ITH | K13: 200 | L13: MXN | M13: Manprec | N13: MAN00943 | O13: FALSE | P13: GENERICO | Q13: EN ALMACEN 11 | R13: MAN13176 | S13: TRUE | T13: ITH00189 | U13: TRUE
A14: CEO00282 | B14: 2 | C14: Centrifuga | D14: 1 | E14: PZ | F14: THERMO | G14: SORVAL ST1 PLUS | H14: 75016007 | I14: LAB-TECH | J14: CEO | K14: 9901.72 | L14: USD | M14: CEO | N14: CEO00135 | O14: FALSE | Q14: EN ALMACEN 11 | R14: N/A | S14: TRUE | T14: N/A | U14: TRUE
A15: CEO00282 | B15: 3 | C15: Congelador De Laboratorio | D15: 1 | E15: PZ | F15: HERLMER | G15: iLF120-GX | H15: 5222120-1 | I15: LAB-TECH | J15: CEO | K15: 10836.85 | L15: USD | M15: CEO | N15: CEO00135 | O15: FALSE | Q15: EN ALMACEN 11 | R15: N/A | S15: TRUE | T15: N/A | U15: TRUE
A16: MPC27523 | B16: 4 | C16: Monitor De Signos Vitales Para El Traslado Del Paciente | D16: 1 | E16: PZ | F16: PHILIPS | G16: EFFICIA CM12 | H16: 863303.1 | I16: PHILIPS | J16: MPC | K16: 1506.61 | L16: USD | M16: Manprec | N16: STOCK | O16: FALSE | Q16: EN ALMACEN 11 | R16: MAN13177 | S16: TRUE | T16: MPC04272 | U16: TRUE
A17: MPC27523 | C17: CBL 3 Lead ECG Trunk AAMI/IEC 2.7m | D17: 1 | E17: PZ | F17: PHILIPS | H17: M1669A | I17: PHILIPS | J17: MPC | K17: 55.2 | L17: USD | M17: Manprec | N17: STOCK | O17: TRUE | Q17: EN ALMACEN 11 | R17: MAN13177 | S17: TRUE | T17: MPC04272 | U17: TRUE
A18: MPC27523 | C18: CBL 3 Leadset Snap AAMI ICU | D18: 1 | E18: PZ | F18: PHILIPS | H18: M1673A | I18: PHILIPS | J18: MPC | K18: 46.2 | L18: USD | M18: Manprec | N18: STOCK | O18: TRUE | Q18: EN ALMACEN 11 | R18: MAN13177 | S18: TRUE | T18: MPC04272 | U18: TRUE
A19: MPC27523 | C19: Easy Care Cuff 1 Hose Pediatric (1) | D19: 1 | E19: PZ | F19: PHILIPS | H19: M4553B | I19: PHILIPS | J19: MPC | K19: 22.62 | L19: USD | M19: Manprec | N19: STOCK | O19: TRUE | Q19: EN ALMACEN 11 | R19: MAN13177 | S19: TRUE | T19: MPC04272 | U19: TRUE
A20: MPC27523 | C20: Easy Care Cuff 1 Hose Adult (1) | D20: 1 | E20: PZ | F20: PHILIPS | H20: M4555B | I20: PHILIPS | J20: MPC | K20: 11.34 | L20: USD | M20: Manprec | N20: STOCK | O20: TRUE | Q20: EN ALMACEN 11 | R20: MAN13177 | S20: TRUE | T20: MPC04272 | U20: TRUE
A21: MPC27523 | C21: Adult NIBP Air Hose 3.0m | D21: 1 | E21: PZ | F21: PHILIPS | H21: 989803209771 | I21: PHILIPS | J21: MPC | K21: 24.66 | L21: USD | M21: Manprec | N21: STOCK | O21: TRUE | Q21: EN ALMACEN 11 | R21: MAN13177 | S21: TRUE | T21: MPC04272 | U21: TRUE
A22: MPC27523 | C22: SPO2 Reus Neo Hnd-Ft Wrap Sensor M1193A | D22: 1 | E22: PZ | F22: PHILIPS | H22: 989803205881 | I22: PHILIPS | J22: MPC | K22: 101.4 | L22: USD | M22: Manprec | N22: STOCK | O22: TRUE | Q22: EN ALMACEN 11 | R22: MAN13177 | S22: TRUE | T22: MPC04272 | U22: TRUE
A23: MPC27523 | C23: CBL SpO2 Extension Cable 2m | D23: 1 | E23: PZ | F23: PHILIPS | H23: M1941A | I23: PHILIPS | J23: MPC | K23: 46.2 | L23: USD | M23: Manprec | N23: STOCK | O23: TRUE | Q23: EN ALMACEN 11 | R23: MAN13177 | S23: TRUE | T23: MPC04272 | U23: TRUE
A24: MPC27523 | C24: Reusable Adult SpO2 Sensor | D24: 1 | E24: PZ | F24: PHILIPS | H24: M1191B | I24: PHILIPS | J24: MPC | K24: 96.6 | L24: USD | M24: Manprec | N24: STOCK | O24: TRUE | Q24: EN ALMACEN 11 | R24: MAN13177 | S24: TRUE | T24: MPC04272 | U24: TRUE
A25: MPC27523 | C25: Skin Temperature Probe, Reusable | D25: 1 | E25: PZ | F25: HOSPIINNOVA | H25: 21078ST | I25: HOSPIINNOVA | J25: MPC | K25: 1050 | L25: MXN | M25: Manprec | N25: MAN00939 | O25: TRUE | Q25: EN ALMACEN 11 | R25: MAN13177 | S25: TRUE | T25: MPC04272 | U25: TRUE
A26: MPC27523 | C26: Rolling Stand--For Patient Monitor | D26: 1 | E26: PZ | F26: TPX | H26: RP050 | I26: TPX | J26: MPC | K26: 115 | L26: USD | M26: MPC | N26: STOCK | O26: TRUE | Q26: EN ALMACEN 11 | R26: N/A | S26: TRUE | T26: N/A | U26: TRUE
A27: MPC27523 | C27: ELECTRODOS NEONATAL | D27: 35 | E27: B/3 | F27: HOSPIINNOVA | H27: 31424743 | I27: HOSPIINNOVA | J27: MPC | K27: =4900/300 -> 16.333333 | L27: MXN | M27: Manprec | N27: STOCK | O27: FALSE | Q27: EN ALMACEN 11 | R27: MAN13177 | S27: TRUE | T27: MPC04272 | U27: TRUE
A28: MPC27523 | C28: ELECTRODO DE MONITOREO ECG PACIENTE ADULTO MT200 CAJA CON 10 SOBRES CON 100 PIEZAS | D28: 1 | E28: B/100 | F28: HOSPIINNOVA | H28: 31050522 | I28: HOSPIINNOVA | J28: MPC | K28: 250 | L28: MXN | M28: Manprec | N28: STOCK | O28: FALSE | Q28: EN ALMACEN 11 | R28: MAN13177 | S28: TRUE | T28: MPC04272 | U28: TRUE
A29: ITH00948 | B29: 5 | C29: Cama-cuna clínica eléctrica | D29: 2 | E29: PZ | F29: GIVAS | G29: VEGA | H29: EBT509 | I29: GIVAS | J29: ITH | K29: 2029.5 | L29: EURO | M29: ITH | N29: STOCK | O29: FALSE | Q29: EN ALMACEN 11 | R29: N/A | S29: TRUE | T29: N/A | U29: TRUE
A30: ITH00948 | C30: Colchon | D30: 2 | E30: PZ | F30: ACOLSA | H30: D20 | I30: ACOLSA | J30: ITH | K30: 2250 | L30: MXN | M30: MPC | N30: MPC04208 | O30: FALSE | Q30: EN ALMACEN 11 | R30: MPC27570 | S30: TRUE | T30: ITH00190 | U30: TRUE
A31: ITH00948 | C31: COLCHON EXTENSION | D31: 2 | E31: PZ | F31: ACOLSA | H31: D20EXT | I31: ACOLSA | J31: ITH | K31: 450 | L31: MXN | M31: MPC | N31: MPC04208 | O31: FALSE | Q31: EN ALMACEN 11 | R31: MPC27570 | S31: TRUE | T31: ITH00190 | U31: TRUE
A32: ITH00948 | C32: Colchon de precion alterna | D32: 2 | E32: PZ | F32: YUWELL | H32: M5-C | I32: YUWELL | J32: ITH | K32: 120 | L32: USD | M32: ITH | N32: STOCK | O32: FALSE | Q32: EN ALMACEN 11 | R32: N/A | S32: TRUE | T32: N/A | U32: TRUE
A33: MPC27523 | B33: 6 | C33: Cardiotocógrafo con accesorios y carro de transporte | D33: 4 | E33: PZ | F33: PHILIPS | G33: AVALON FM20 | H33: M2702A.1 | I33: PHILIPS | J33: MPC | K33: 2483.65 | L33: USD | M33: Manprec | N33: STOCK | O33: FALSE | Q33: EN ALMACEN 11 | R33: MAN13177 | S33: TRUE | T33: MPC04272 | U33: TRUE
A34: MPC27523 | C34: Avalon US Transducer | D34: 4 | E34: PZ | F34: PHILIPS | H34: 867246 | I34: PHILIPS | J34: MPC | K34: 520.2 | L34: USD | M34: Manprec | N34: STOCK | O34: TRUE | Q34: EN ALMACEN 11 | R34: MAN13177 | S34: TRUE | T34: MPC04272 | U34: TRUE
A35: MPC27523 | C35: Avalon TOCO MP Transducer | D35: 4 | E35: PZ | F35: PHILIPS | H35: 867248 | I35: PHILIPS | J35: MPC | K35: 566.4 | L35: USD | M35: Manprec | N35: STOCK | O35: TRUE | Q35: EN ALMACEN 11 | R35: MAN13177 | S35: TRUE | T35: MPC04272 | U35: TRUE
A36: MPC27523 | C36: Remote Event Marker | D36: 4 | E36: PZ | F36: PHILIPS | H36: 989803143411 | I36: PHILIPS | J36: MPC | K36: 107.4 | L36: USD | M36: Manprec | N36: STOCK | O36: TRUE | Q36: EN ALMACEN 11 | R36: MAN13177 | S36: TRUE | T36: MPC04272 | U36: TRUE
A37: MPC27523 | C37: Reusable Abdominal Belt- 60mm Wd 1.3M Lg | D37: 4 | E37: PZ | F37: HOSPIINNOVA | H37: CINFM | I37: CABLES Y SENSORES | J37: MPC | K37: =1424/10 -> 142.4 | L37: MXN | M37: Manprec | N37: STOCK | O37: TRUE | Q37: EN ALMACEN 11 | R37: MAN13177 | S37: TRUE | T37: MPC04272 | U37: TRUE
A38: MPC27523 | C38: R01 GCX Rollstand: FM20/30 | D38: 4 | E38: PZ | F38: TPX | H38: RP050-FM | I38: TPX | J38: MPC | K38: 115 | L38: USD | M38: MPC | N38: STOCK | O38: TRUE | P38: SE ENTREGAN CARROS TPX | Q38: EN ALMACEN 11 | R38: N/A | S38: TRUE | T38: N/A | U38: TRUE
A39: MPC27523 | C39: Fetal monitoring recording paper | D39: 4 | E39: CAJA | F39: PHILIPS | H39: M1910A | I39: PHILIPS | J39: MPC | K39: 112.2 | L39: USD | M39: Manprec | N39: STOCK | O39: TRUE | Q39: EN ALMACEN 11 | R39: MAN13177 | S39: TRUE | T39: MPC04272 | U39: TRUE
A40: MPC27523 | B40: 7 | C40: Refrigerador con congelador grado medico con control de temperatura de 24 ft³ | D40: 3 | E40: PZ | F40: REFRIMED | G40: RVASCV-24 | H40: RVASCV-24 | I40: REFRIMED | J40: MPC | K40: 88373.98 | L40: MXN | M40: MPC | N40: MPC04151 | O40: FALSE | Q40: EN ALMACEN 11 | R40: N/A | S40: TRUE | T40: N/A | U40: TRUE
...

Sheet TABASCO IM007
A1: PEDIDO | B1: PARTIDA | C1: DESCRIPCIÓN | D1: CANTIDAD | E1: UDM | F1: MARCA | G1: MODELO | H1: CÓDIGO | I1: PROVEEDOR | J1: Empresa que vende | K1: COSTO | L1: MONEDA COSTO | M1: EMPRESA QUE COMPRA | N1: OC | O1: B2B | P1: OBSERVACIONES | Q1: ESTATUS | R1: OV-INT | S1: Status de Interempresa | T1: OC-INT | U1: Status de Interempresa
A2: MAN13243 | B2: 1 | C2: CENTRAL DE MONITOREO PARA MÚLTIPLES CAMAS (14 MONITORES) | D2: 1 | E2: PZ | F2: PHILIPS | H2: 866389 | I2: PHILIPS | J2: Manprec | K2: 28758.2 | L2: USD | M2: Manprec | N2: MAN00928 | O2: FALSE | Q2: EN ALMACEN 11 | R2: N/A | S2: FALSE | U2: FALSE
C3: PIC iX Hardware | D3: 1 | E3: PZ | F3: PHILIPS | H3: 866424 | I3: PHILIPS | J3: Manprec | K3: 0 | L3: USD | M3: Manprec | N3: MAN00928 | O3: FALSE | Q3: EN ALMACEN 11 | R3: N/A | S3: FALSE | U3: FALSE
C4: 24" Widescreen LCD Display - touch | D4: 1 | E4: PZ | F4: PHILIPS | H4: 866126 | I4: PHILIPS | J4: Manprec | K4: 0 | L4: USD | M4: Manprec | N4: MAN00928 | O4: FALSE | Q4: EN ALMACEN 11 | R4: N/A | S4: FALSE | U4: FALSE
C5: 24" Widescreen LCD Display - touch | D5: 1 | E5: PZ | F5: PHILIPS | H5: 866126 | I5: PHILIPS | J5: Manprec | K5: 0 | L5: USD | M5: Manprec | N5: MAN00993 | O5: FALSE | Q5: EN ALMACEN 11 | R5: N/A | S5: FALSE | U5: FALSE
C6: Layer 2 Switch | D6: 1 | E6: PZ | F6: PHILIPS | H6: 867392 | I6: PHILIPS | J6: Manprec | K6: 0 | L6: USD | M6: Manprec | N6: MAN00928 | O6: FALSE | Q6: EN ALMACEN 11 | R6: N/A | S6: FALSE | U6: FALSE
C7: Belden Bobina UTO Cat 5E | D7: 1 | E7: PZ | F7: PCEL | H7: B0C3BPG4FS | I7: PCEL | J7: Manprec | K7: 257.75862 | L7: MXN | M7: MPC | N7: MPC04501 | O7: FALSE | Q7: EN ALMACEN 11 | R7: MPC27909 | S7: TRUE | T7: MAN01031 | U7: TRUE
C8: JACK RJ45 CAT5E UTP KEYST | D8: 14 | E8: PZ | F8: Mercadolibre | H8: B07PBTSJYT | I8: PCEL | J8: Manprec | K8: 177 | L8: MXN | M8: MPC | N8: MPC04486/STOCK | O8: FALSE | Q8: EN ALMACEN 11 | R8: MPC27909 | S8: TRUE | T8: MAN01031 | U8: TRUE
C9: Tapa para caja RJ45 (sencilla) marca: Intellinet o Belden | D9: 14 | E9: PZ | F9: PCEL | H9: X00221V4R9 | I9: PCEL | J9: Manprec | K9: 50 | L9: MXN | M9: MPC | N9: STOCK | O9: FALSE | P9: STOCK | Q9: EN ALMACEN 11 | R9: MPC27909 | S9: TRUE | T9: MAN01031 | U9: TRUE
C10: IMPRESORA HP LASERJET 501DN | D10: 1 | E10: PZ | F10: PCEL | H10: J8H61A | I10: PCEL | J10: Manprec | K10: 5602.59 | L10: MXN | M10: MPC | N10: MPC04492 | O10: FALSE | Q10: EN ALMACEN 11 | R10: MPC27909 | S10: TRUE | T10: MAN01031 | U10: TRUE
C11: UPS RESPALDO DE 1 HORA | D11: 1 | E11: PZ | F11: ALTERNATIVA | H11: PA MG+15 1000-UN | I11: ALTERNATIVA | J11: Manprec | K11: 154 | L11: USD | M11: Gamit | N11: STOCK | O11: FALSE | Q11: EN ALMACEN 11 | R11: GAM00157 | S11: TRUE | T11: MAN01031 | U11: TRUE
C12: SOPORTE RODABLE TPX | D12: 1 | E12: PZ | F12: TPX | H12: RP050 | I12: TPX | J12: Manprec | K12: 115 | L12: USD | M12: MPC | N12: STOCK | O12: FALSE | Q12: EN ALMACEN 11 | R12: MPC27909 | S12: TRUE | T12: MAN01031 | U12: TRUE
A13: MAN13243 | B13: 2 | C13: CENTRAL DE MONITOREO PARA MÚLTIPLES CAMAS (8 MONITORES) | D13: 1 | E13: PZ | F13: PHILIPS | H13: 866389 | I13: PHILIPS | J13: Manprec | K13: 17853.2 | L13: USD | M13: Manprec | N13: MAN00928 | O13: FALSE | Q13: EN ALMACEN 11 | R13: N/A | S13: FALSE | U13: FALSE
C14: PIC iX Hardware | D14: 1 | E14: PZ | F14: PHILIPS | H14: 866424 | I14: PHILIPS | J14: Manprec | K14: 0 | L14: USD | M14: Manprec | N14: MAN00928 | O14: FALSE | Q14: EN ALMACEN 11 | R14: N/A | S14: FALSE | U14: FALSE
C15: 24" Widescreen LCD Display - touch | D15: 1 | E15: PZ | F15: PHILIPS | H15: 866126 | I15: PHILIPS | J15: Manprec | K15: 0 | L15: USD | M15: Manprec | N15: MAN00928 | O15: FALSE | Q15: EN ALMACEN 11 | R15: N/A | S15: FALSE | U15: FALSE
C16: 24" Widescreen LCD Display - touch | D16: 1 | E16: PZ | F16: PHILIPS | H16: 866126 | I16: PHILIPS | J16: Manprec | K16: 0 | L16: USD | M16: Manprec | N16: MAN00993 | O16: FALSE | Q16: EN ALMACEN 11 | R16: N/A | S16: FALSE | U16: FALSE
C17: Layer 2 Switch | D17: 1 | E17: PZ | F17: PHILIPS | H17: 867392 | I17: PHILIPS | J17: Manprec | K17: 0 | L17: USD | M17: Manprec | N17: MAN00928 | O17: FALSE | Q17: EN ALMACEN 11 | R17: N/A | S17: FALSE | U17: FALSE
C18: Belden Bobina UTO Cat 5E | D18: 1 | E18: PZ | F18: PCEL | H18: B0C3BPG4FS | I18: PCEL | J18: Manprec | K18: 257.75862 | L18: MXN | M18: MPC | N18: MPC04501 | O18: FALSE | Q18: EN ALMACEN 11 | R18: MPC27909 | S18: TRUE | T18: MAN01031 | U18: TRUE
C19: JACK RJ45 CAT5E UTP KEYST | D19: 9 | E19: PZ | F19: Mercadolibre | H19: B07PBTSJYT | I19: PCEL | J19: Manprec | K19: 177 | L19: MXN | M19: MPC | N19: MPC04486/STOCK | O19: FALSE | Q19: EN ALMACEN 11 | R19: MPC27909 | S19: TRUE | T19: MAN01031 | U19: TRUE
C20: Tapa para caja RJ45 (sencilla) marca: Intellinet o Belden | D20: 9 | E20: PZ | F20: PCEL | H20: X00221V4R9 | I20: PCEL | J20: Manprec | K20: 50 | L20: MXN | M20: MPC | N20: STOCK | O20: FALSE | P20: STOCK | Q20: EN ALMACEN 11 | R20: MPC27909 | S20: TRUE | T20: MAN01031 | U20: TRUE
C21: IMPRESORA HP LASERJET 501DN | D21: 1 | E21: PZ | F21: PCEL | H21: J8H61A | I21: PCEL | J21: Manprec | K21: 5602.59 | L21: MXN | M21: MPC | N21: MPC04492 | O21: FALSE | Q21: EN ALMACEN 11 | R21: MPC27909 | S21: TRUE | T21: MAN01031 | U21: TRUE
C22: UPS RESPALDO DE 1 HORA | D22: 1 | E22: PZ | F22: ALTERNATIVA | H22: PA MG+15 1000-UN | I22: ALTERNATIVA | J22: Manprec | K22: 154 | L22: MXN | M22: Gamit | N22: STOCK | O22: FALSE | Q22: EN ALMACEN 11 | R22: GAM00157 | S22: TRUE | T22: MAN01031 | U22: TRUE
C23: SOPORTE RODABLE TPX | D23: 1 | E23: PZ | F23: TPX | H23: RP050 | I23: TPX | J23: Manprec | K23: 115 | L23: USD | M23: MPC | N23: STOCK | O23: FALSE | Q23: EN ALMACEN 11 | R23: MPC27909 | S23: TRUE | T23: MAN01031 | U23: TRUE
A24: MAN13243 | B24: 12 | C24: MESA PARA AUTOPSIAS CON TRITURADOR | D24: 1 | E24: PZ | F24: REFRIMED | H24: MATT | I24: REFRIMED | J24: Manprec | K24: 464256.8 | L24: MXN | M24: MPC | N24: MPC04380 | O24: FALSE | Q24: EN ALMACEN 11 | R24: MPC27909 | S24: TRUE | T24: MAN01031 | U24: TRUE
O25: FALSE | S25: FALSE | U25: FALSE
O26: FALSE | S26: FALSE | U26: FALSE
O27: FALSE | S27: FALSE | U27: FALSE
O28: FALSE | S28: FALSE | U28: FALSE
O29: FALSE | S29: FALSE | U29: FALSE
O30: FALSE | S30: FALSE | U30: FALSE
O31: FALSE | S31: FALSE | U31: FALSE
O32: FALSE | S32: FALSE | U32: FALSE
O33: FALSE | S33: FALSE | U33: FALSE
O34: FALSE | S34: FALSE | U34: FALSE
O35: FALSE | S35: FALSE | U35: FALSE
O36: FALSE | S36: FALSE | U36: FALSE
... O51: FALSE | S51: FALSE | U51: FALSE

Sheet IMSS BIENESTAR TABASCO 053
A1: PEDIDO | B1: PARTIDA | C1: DESCRIPCIÓN | D1: CANTIDAD | E1: UDM | F1: MARCA | G1: MODELO | H1: CÓDIGO | I1: PROVEEDOR | J1: Empresa que vende | K1: COSTO | L1: MONEDA COSTO | M1: EMPRESA QUE COMPRA | N1: OC | O1: B2B | P1: OBSERVACIONES | Q1: ESTATUS | R1: OV-INT | S1: Status de Interempresa | T1: OC-INT | U1: Status de Interempresa
A2: MAN13244 | B2: 90 / 107 | C2: MONITOR DE SIGNOS VITALES AVANZADO | D2: 22 | E2: PZ | F2: PHILIPS | G2: MX500 | H2: 866064.6 | I2: PHILIPS | J2: Manprec | K2: 4311.1 | L2: USD | M2: Manprec | N2: MAN00993 | O2: FALSE | P2: CDD 01 Junio | Q2: PENDIENTE | R2: N/A | S2: TRUE | T2: N/A | U2: TRUE
B3: 90 | C3: IntelliVue MMX | D3: 22 | E3: PZ | H3: 867036.1 | I3: PHILIPS | J3: Manprec | K3: 1100 | L3: USD | M3: Manprec | N3: MAN00993 | O3: FALSE | P3: CDD 01 Junio | Q3: PENDIENTE | R3: N/A | S3: TRUE | T3: N/A | U3: TRUE
B4: 90 | C4: IntelliVue Capnography Extension | D4: 22 | E4: PZ | H4: 867040.2 | I4: PHILIPS | J4: Manprec | K4: 1694.63 | L4: USD | M4: Manprec | N4: MAN00993 | O4: FALSE | P4: CDD 01 Junio | Q4: PENDIENTE | R4: N/A | S4: TRUE | T4: N/A | U4: TRUE
B5: 90 | C5: Mainstream Sensor | D5: 22 | E5: PZ | H5: M2501A | I5: PHILIPS | J5: Manprec | K5: 1630.8 | L5: USD | M5: Manprec | N5: Stock | O5: TRUE | Q5: EN ALMACEN 11 | R5: N/A | S5: TRUE | T5: N/A | U5: TRUE
B6: 90 | C6: SPO2 Reus Ped-Adult Glove Sensor M1192A | D6: 22 | E6: PZ | H6: 989803205871 | I6: PHILIPS | J6: Manprec | K6: 102 | L6: USD | M6: Manprec | N6: Stock | O6: TRUE | Q6: EN ALMACEN 11 | R6: N/A | S6: TRUE | T6: N/A | U6: TRUE
B7: 90 | C7: CBL SpO2 Extension Cable 2m | D7: 44 | E7: PZ | H7: M1941A | I7: PHILIPS | J7: Manprec | K7: 46.2 | L7: USD | M7: Manprec | N7: MAN01003 | O7: TRUE | Q7: PENDIENTE | R7: N/A | S7: TRUE | T7: N/A | U7: TRUE
B8: 90 | C8: Reusable Adult SpO2 Sensor | D8: 22 | E8: PZ | H8: M1191B | I8: PHILIPS | J8: Manprec | K8: 96.6 | L8: USD | M8: Manprec | N8: Stock | O8: TRUE | Q8: EN ALMACEN 11 | R8: N/A | S8: TRUE | T8: N/A | U8: TRUE
B9: 90 | C9: Skin Temperature Probe, Reusable | D9: 44 | E9: PZ | H9: 21078ST | I9: HOSPIINNOVA | J9: Manprec | K9: 840 | L9: MXN | M9: Manprec | N9: MAN00996 | O9: FALSE | Q9: EN ALMACEN 11 | R9: N/A | S9: TRUE | T9: N/A | U9: TRUE
B10: 90 | C10: Easy Care Cuff 1 Hose Pediatric (1) | D10: 22 | E10: PZ | H10: M4553B | I10: PHILIPS | J10: Manprec | K10: 23.94 | L10: USD | M10: Manprec | N10: MAN01003 | O10: TRUE | Q10: PENDIENTE | R10: N/A | S10: TRUE | T10: N/A | U10: TRUE
B11: 90 | C11: Easy Care Cuff 1 Hose Adult (1) | D11: 22 | E11: PZ | H11: M4555B | I11: PHILIPS | J11: Manprec | K11: 11.34 | L11: USD | M11: Manprec | N11: MAN01003 | O11: TRUE | Q11: PENDIENTE | R11: N/A | S11: TRUE | T11: N/A | U11: TRUE
B12: 90 | C12: Adult NIBP Air Hose 3.0m | D12: 22 | E12: PZ | H12: 989803209771 | I12: PHILIPS | J12: Manprec | K12: 24.66 | L12: USD | M12: Manprec | N12: Stock | O12: TRUE | Q12: EN ALMACEN 11 | R12: N/A | S12: TRUE | T12: N/A | U12: TRUE
B13: 90 | C13: CBL 5 Lead ECG Trunk AAMI/IEC 2.7m | D13: 22 | E13: PZ | H13: M1668A | I13: PHILIPS | J13: Manprec | K13: 70.8 | L13: USD | M13: Manprec | N13: MAN01003 | O13: TRUE | Q13: PENDIENTE | R13: N/A | S13: TRUE | T13: N/A | U13: TRUE
B14: 90 | C14: CBL 5 Leadset Snap AAMI ICU | D14: 22 | E14: PZ | H14: M1644A | I14: PHILIPS | J14: Manprec | K14: 67.8 | L14: USD | M14: Manprec | N14: Stock | O14: TRUE | Q14: EN ALMACEN 11 | R14: N/A | S14: TRUE | T14: N/A | U14: TRUE
B15: 90 | C15: CBL 10 Lead ECG Trunk AAMI/IEC 2m | D15: 22 | E15: PZ | H15: M1663A | I15: PHILIPS | J15: Manprec | K15: 153 | L15: USD | M15: Manprec | N15: MAN01003 | O15: TRUE | Q15: PENDIENTE | R15: N/A | S15: TRUE | T15: N/A | U15: TRUE
B16: 90 | C16: CBL 5 Leadset Grabber AAMI ICU | D16: 22 | E16: PZ | H16: M1968A | I16: PHILIPS | J16: Manprec | K16: 54 | L16: USD | M16: Manprec | N16: Stock | O16: TRUE | Q16: EN ALMACEN 11 | R16: N/A | S16: TRUE | T16: N/A | U16: TRUE
B17: 90 | C17: CBL 5 Leadset Grabber Chest AAMI ICU | D17: 22 | E17: PZ | H17: M1976A | I17: PHILIPS | J17: Manprec | K17: 68.4 | L17: USD | M17: Manprec | N17: Stock | O17: TRUE | Q17: EN ALMACEN 11 | R17: N/A | S17: TRUE | T17: N/A | U17: TRUE
B18: 90 | C18: SPO2 Reus Neo Hnd-Ft Wrap Sensor M1193A | D18: 22 | E18: PZ | H18: 989803205881 | I18: PHILIPS | J18: Manprec | K18: 101.4 | L18: USD | M18: Manprec | N18: MAN01003 | O18: TRUE | Q18: PENDIENTE | R18: N/A | S18: TRUE | T18: N/A | U18: TRUE
B19: 90 | C19: Neonatal NIBP Air Hose 3.0m | D19: 22 | E19: PZ | H19: 989803209751 | I19: PHILIPS | J19: Manprec | K19: 23.94 | L19: USD | M19: Manprec | N19: Stock | O19: TRUE | Q19: EN ALMACEN 11 | R19: N/A | S19: TRUE | T19: N/A | U19: TRUE
B20: 90 | C20: Neonatal Soft Single-Patient Cuff Size#2 | D20: =22*10 -> 220 | E20: PZ | H20: M1868S | I20: PHILIPS | J20: Manprec | K20: 136.8 | L20: USD | M20: Manprec | N20: Stock | O20: TRUE | Q20: EN ALMACEN 11 | R20: N/A | S20: TRUE | T20: N/A | U20: TRUE
B21: 90 | C21: Neonatal Soft Single-Patient Cuff Size#3 | D21: =22*10 -> 220 | E21: PZ | H21: M1870S | I21: PHILIPS | J21: Manprec | K21: 141.6 | L21: USD | M21: Manprec | N21: Stock | O21: TRUE | Q21: EN ALMACEN 11 | R21: N/A | S21: TRUE | T21: N/A | U21: TRUE
B22: 90 | C22: CBL 3 Lead ECG Trunk AAMI/IEC 2.7m | D22: 22 | E22: PZ | H22: M1669A | I22: PHILIPS | J22: Manprec | K22: 54 | L22: USD | M22: Manprec | N22: Stock | O22: TRUE | Q22: EN ALMACEN 11 | R22: N/A | S22: TRUE | T22: N/A | U22: TRUE
B23: 90 | C23: CBL Unshielded 3 Ld Miniclip AAMI 0.7m | D23: 22 | E23: PZ | H23: M1624A | I23: PHILIPS | J23: Manprec | K23: 27.96 | L23: USD | M23: Manprec | N23: Stock | O23: TRUE | Q23: EN ALMACEN 11 | R23: N/A | S23: TRUE | T23: N/A | U23: TRUE
B24: 90 | C24: Airway Adapter-Reusable-Adult/Pediatric | D24: 22 | E24: PZ | H24: 989803206591 | I24: PHILIPS | J24: Manprec | K24: 115.8 | L24: USD | M24: Manprec | N24: Stock | O24: TRUE | Q24: EN ALMACEN 11 | R24: N/A | S24: TRUE | T24: N/A | U24: TRUE
B25: 90 | C25: CBL Cardiac Output Cable | D25: 22 | E25: PZ | H25: M1642A | I25: PHILIPS | J25: Manprec | K25: 130.8 | L25: USD | M25: Manprec | N25: Stock | O25: TRUE | Q25: EN ALMACEN 11 | R25: N/A | S25: TRUE | T25: N/A | U25: TRUE
B26: 90 | C26: Wall Mount with adjustable height | D26: 22 | E26: PZ | H26: WP010-MX | I26: TPX | J26: Manprec | K26: 78 | L26: USD | M26: MPC | N26: Stock | O26: FALSE | Q26: PENDIENTE | R26: MPC28349 | S26: TRUE | T26: MAN01030 | U26: TRUE
B27: 90 | C27: ELECTRODO DE MONITOREO ECG PACIENTE ADULTO MT200 CAJA CON 10 SOBRES CON 100 PIEZAS | D27: =3*22 -> 66 | E27: B/100 | F27: CARDINAL | H27: 31050522 | I27: HOSPIINNOVA | J27: Manprec | L27: MXN | M27: Manprec | N27: Stock | O27: FALSE | Q27: EN ALMACEN 11 | R27: N/A | S27: TRUE | T27: N/A | U27: TRUE
B28: 90 | C28: ELECTRODOS NEONATAL DE ECG | D28: =(22*300/3) -> 2200 | E28: B/3 | F28: CARDINAL | H28: 31424743 | I28: HOSPIINNOVA | J28: Manprec | K28: =4512/100 -> 45.12 | L28: MXN | M28: Manprec | N28: MAN01078 | O28: FALSE | Q28: PENDIENTE | R28: N/A | S28: TRUE | T28: N/A | U28: TRUE
B29: 90 | C29: Co-Set(TM) Injectate Temp Probe - 7'9 | D29: 22 | E29: PZ | H29: 23001A | I29: INNOVACION | J29: Manprec | K29: 546 | L29: USD | M29: Manprec | N29: MAN01032 | O29: FALSE | Q29: PENDIENTE | R29: N/A | S29: TRUE | T29: N/A | U29: TRUE
B30: 90 | C30: Ice Bath Temperature Probe | D30: 22 | E30: PZ | H30: 23002A | I30: INNOVACION | J30: Manprec | K30: 234 | L30: USD | M30: Manprec | N30: MAN01032 | O30: FALSE | Q30: EN ALMACEN 11 | R30: N/A | S30: TRUE | T30: N/A | U30: TRUE
B31: 90 | C31: Transductor reusable logical. | D31: 44 | E31: PZ | H31: MX960 | I31: ATSA | J31: Manprec | K31: 3142.1 | L31: MXN | M31: Manprec | N31: MAN01001 | O31: TRUE | Q31: EN ALMACEN 11 | R31: N/A | S31: TRUE | T31: N/A | U31: TRUE
B32: 90 | C32: Soporte porta transductor logical reusable | D32: 22 | E32: PZ | H32: MX261 | I32: ATSA | J32: Manprec | K32: 491.9 | L32: MXN | M32: Manprec | N32: MAN01001 | O32: TRUE | Q32: EN ALMACEN 11 | R32: N/A | S32: TRUE | T32: N/A | U32: TRUE
B33: 90 | C33: Bracket para dos transductores logical reusable | D33: 22 | E33: PZ | H33: MX262 | I33: ATSA | J33: Manprec | K33: 337.3 | L33: MXN | M33: Manprec | N33: MAN01001 | O33: TRUE | Q33: EN ALMACEN 11 | R33: N/A | S33: TRUE | T33: N/A | U33: TRUE
B34: 90 | C34: Cable logical interface HP /PHILIPS reusable un canal | D34: =22*2 -> 44 | E34: PZ | H34: BC-HP-MX1 | I34: ATSA | J34: Manprec | K34: 1014.3 | L34: MXN | M34: Manprec | N34: MAN01001 | O34: TRUE | Q34: EN ALMACEN 11 | R34: N/A | S34: TRUE | T34: N/A | U34: TRUE
B35: 90 | C35: Kit transductor logical domo, llaves, flush, | D35: =20*22 -> 440 | E35: PZ | H35: MX9604A | I35: ATSA | J35: Manprec | K35: =3638/10 -> 363.8 | L35: MXN | M35: Manprec | N35: MAN01001 | O35: TRUE | Q35: EN ALMACEN 11 | R35: N/A | S35: TRUE | T35: N/A | U35: TRUE
A36: MAN13244 | B36: 232 | C36: MONITOR DE SIGNOS VITALES | D36: 31 | E36: PZ | F36: PHILIPS | G36: MX500 | H36: 866064.6 | I36: PHILIPS | J36: Manprec | K36: 3487.02 | L36: USD | M36: Manprec | N36: MAN00993 | O36: FALSE | P36: CDD 01 Junio | Q36: PENDIENTE | R36: N/A | S36: TRUE | T36: N/A | U36: TRUE
B37: 232 | C37: IntelliVue MMX | D37: 31 | E37: PZ | H37: 867036.1 | I37: PHILIPS | J37: Manprec | K37: 1100 | L37: USD | M37: Manprec | N37: MAN00993 | O37: FALSE | P37: CDD 01 Junio | Q37: PENDIENTE | R37: N/A | S37: TRUE | T37: N/A | U37: TRUE
B38: 232 | C38: Temperature Parameter Module | D38: 31 | E38: PZ | H38: M1029A | I38: PHILIPS | J38: Manprec | K38: 247.93 | L38: USD | M38: Manprec | N38: MAN00993 | O38: FALSE | P38: CDD 01 Junio | Q38: PENDIENTE | R38: N/A | S38: TRUE | T38: N/A | U38: TRUE
B39: 232 | C39: SPO2 Reus Ped-Adult Glove Sensor M1192A | D39: 31 | E39: PZ | H39: 989803205871 | I39: PHILIPS | J39: Manprec | K39: 102 | L39: USD | M39: Manprec | N39: Stock | O39: TRUE | Q39: EN ALMACEN 11 | R39: N/A | S39: TRUE | T39: N/A | U39: TRUE
B40: 232 | C40: SPO2 Reus Neo Hnd-Ft Wrap Sensor M1193A | D40: 31 | E40: PZ | H40: 989803205881 | I40: PHILIPS | J40: Manprec | K40: 101.4 | L40: USD | M40: Manprec | N40: MAN01003 | O40: TRUE | Q40: PENDIENTE | R40: N/A | S40: TRUE | T40: N/A | U40: TRUE
...

Sheet Comercializadora de la Puebla d
A1: PEDIDO | B1: PARTIDA | C1: DESCRIPCIÓN | D1: CANTIDAD | E1: UDM | F1: MARCA | G1: MODELO | H1: CÓDIGO | I1: PROVEEDOR | J1: Empresa que vende | K1: COSTO | L1: MONEDA COSTO | M1: EMPRESA QUE COMPRA | N1: OC | O1: B2B | P1: OBSERVACIONES | Q1: ESTATUS | R1: OV-INT | S1: Status de Interempresa | T1: OC-INT | U1: Status de Interempresa
A2: MPC27819 | B2: 1 | C2: Monitor materno fetal (Cardiotocógrafo) | D2: 1 | E2: PZ | H2: M2702A.1 | I2: PHILIPS | J2: MPC | K2: 2483.65 | L2: USD | M2: Manprec | N2: Stock | O2: FALSE | Q2: EN ALMACEN 11 | R2: MAN13294 | S2: TRUE | T2: MPC04479 | U2: TRUE
C3: Avalon US Transducer | D3: 2 | E3: PZ | H3: 867246 | I3: PHILIPS | J3: MPC | K3: 553.2 | L3: USD | M3: Manprec | O3: FALSE | R3: MAN13294 | S3: TRUE | T3: MPC04479 | U3: TRUE
C4: Avalon TOCO | D4: 2 | E4: PZ | H4: 867248 | I4: PHILIPS | J4: MPC | K4: 601.8 | L4: USD | M4: Manprec | O4: FALSE | R4: MAN13294 | S4: TRUE | T4: MPC04479 | U4: TRUE
C5: Remote Event Marker | D5: 1 | E5: PZ | H5: 989803143411 | I5: PHILIPS | J5: MPC | K5: 114 | L5: USD | M5: Manprec | O5: FALSE | R5: MAN13294 | S5: TRUE | T5: MPC04479 | U5: TRUE
C6: Reusable Abdominal Belt- 60mm Wd 1.3M Lg | D6: 2 | E6: PZ | H6: CINFM | I6: GUSTAVO EDUARDO AVILA WOO | J6: MPC | K6: =1092/8 -> 136.5 | L6: MXN | M6: Manprec | N6: MAN00961 | O6: FALSE | P6: STOCK | Q6: EN ALMACEN 11 | R6: MAN13294 | S6: TRUE | T6: MPC04479 | U6: TRUE
C7: Carro de transporte TPX para Cardiotoco Avalon FM20/FM30 | D7: 1 | E7: PZ | H7: RP050-FM | I7: TPX | J7: MPC | K7: 115 | L7: USD | M7: N/A | N7: MPC04399 | O7: FALSE | Q7: EN ALMACEN 11 | R7: N/A | S7: TRUE | T7: N/A | U7: TRUE
C8: Fetal monitoring recording paper | D8: 1 | E8: C/40 | H8: M1910A | I8: AKUASUL | J8: MPC | K8: 2640 | L8: MXN | M8: Manprec | N8: MAN01009 | O8: FALSE | Q8: EN ALMACEN 11 | R8: MAN13294 | S8: TRUE | T8: MPC04479 | U8: TRUE
A9: MPC27819 | B9: 2 | C9: Monitor IntelliVue MX500 | D9: 0 | E9: PZ | H9: 866064.3 | I9: PHILIPS | J9: MPC | K9: 3089.63 | L9: USD | M9: MPC | N9: MPC04368 | O9: FALSE | Q9: PENDIENTE | S9: FALSE | U9: FALSE
A10: MPC27819 | B10: 2.1 | C10: Módulo IntelliVue MMX | D10: 0 | E10: PZ | H10: 867036.4 | I10: PHILIPS | J10: MPC | K10: 2183.85 | L10: USD | M10: MPC | N10: MPC04368 | O10: FALSE | Q10: PENDIENTE | S10: FALSE | U10: FALSE
C11: Temperature Parameter Module | D11: 0 | E11: PZ | H11: M1029A | I11: PHILIPS | J11: MPC | K11: 267.27 | L11: USD | M11: MPC | N11: MPC04368 | O11: FALSE | Q11: PENDIENTE | S11: FALSE | U11: FALSE
C12: Reusable Adult SpO2 Sensor | D12: 0 | E12: PZ | H12: M1191BL | I12: PHILIPS | J12: MPC | K12: 93.08 | L12: USD | M12: MPC | N12: MPC04368 | O12: FALSE | Q12: PENDIENTE | S12: FALSE | U12: FALSE
C13: SPO2 Reus Ped-Adult Glove Sensor M1192A | D13: 0 | E13: PZ | H13: 989803205871 | I13: PHILIPS | J13: MPC | K13: 92.54 | L13: USD | M13: MPC | N13: MPC04368 | O13: FALSE | Q13: PENDIENTE | S13: FALSE | U13: FALSE
C14: CBL SpO2 Extension Cable 2m | D14: 0 | E14: PZ | H14: M1941A | I14: PHILIPS | J14: MPC | K14: 41.91 | L14: USD | M14: MPC | N14: MPC04368 | O14: FALSE | Q14: PENDIENTE | S14: FALSE | U14: FALSE
C15: CBL 5 Lead ECG Trunk AAMI/IEC 2.7m | D15: 0 | E15: PZ | H15: M1668A | I15: PHILIPS | J15: MPC | K15: 64.23 | L15: USD | M15: MPC | N15: MPC04368 | O15: FALSE | Q15: PENDIENTE | S15: FALSE | U15: FALSE
C16: CBL 5 Leadset Snap AAMI ICU | D16: 0 | E16: PZ | H16: M1644A | I16: PHILIPS | J16: MPC | K16: 61.51 | L16: USD | M16: MPC | N16: MPC04368 | O16: FALSE | Q16: PENDIENTE | S16: FALSE | U16: FALSE
C17: Adult NIBP Air Hose 3.0m | D17: 0 | E17: PZ | H17: 989803209771 | I17: PHILIPS | J17: MPC | K17: 22.37 | L17: USD | M17: MPC | N17: MPC04368 | O17: FALSE | Q17: PENDIENTE | S17: FALSE | U17: FALSE
C18: Mainstream Sensor | D18: 0 | E18: PZ | H18: M2501A | I18: PHILIPS | J18: MPC | K18: 1340.14 | L18: USD | M18: MPC | N18: MPC04368 | O18: FALSE | Q18: PENDIENTE | S18: FALSE | U18: FALSE
C19: Airway Adapter-Reusable-Adult/Pediatric | D19: 0 | E19: PZ | H19: 989803206591 | I19: PHILIPS | J19: MPC | K19: 105.06 | L19: USD | M19: MPC | N19: MPC04368 | O19: FALSE | Q19: PENDIENTE | S19: FALSE | U19: FALSE
C20: Easy Care Cuff 1 Hose Infant (1) | D20: 0 | E20: PZ | H20: M4552B | I20: PHILIPS | J20: MPC | K20: 9.04 | L20: USD | M20: MPC | N20: MPC04368 | O20: FALSE | Q20: PENDIENTE | S20: FALSE | U20: FALSE
C21: Easy Care Cuff 1 Hose Pediatric (1) | D21: 0 | E21: PZ | H21: M4553B | I21: PHILIPS | J21: MPC | K21: 21.72 | L21: USD | M21: MPC | N21: MPC04368 | O21: FALSE | Q21: PENDIENTE | S21: FALSE | U21: FALSE
C22: Easy Care Cuff 1 Hose Adult (1) | D22: 0 | E22: PZ | H22: M4555B | I22: PHILIPS | J22: MPC | K22: 10.29 | L22: USD | M22: MPC | N22: MPC04368 | O22: FALSE | Q22: PENDIENTE | S22: FALSE | U22: FALSE
C23: SENSOR DE TEMPERATURA | D23: 0 | E23: PZ | H23: 21078ST | I23: HOSPIINNOVA | J23: MPC | K23: 871.3 | L23: MXN | M23: Manprec | O23: FALSE | S23: FALSE | U23: FALSE
C24: PLACA DE TRANSDUCTOR LOGICAL REUSABLE | D24: 0 | E24: PZ | H24: MX960 | I24: ATSA | J24: MPC | K24: 3142.1 | L24: MXN | M24: Manprec | N24: MAN01013 | O24: FALSE | Q24: EN ALMACEN 11 | S24: FALSE | U24: FALSE
C25: SOPORTE P/ PLACA DE TRANSDUCTOR LOGICAL | D25: 0 | E25: PZ | H25: MX261 | I25: ATSA | J25: MPC | K25: 491.9 | L25: MXN | M25: Manprec | N25: MAN01013 | O25: FALSE | Q25: EN ALMACEN 11 | S25: FALSE | U25: FALSE
C26: BRACKET PARA DOS TRANSDUCTORES | D26: 0 | E26: PZ | H26: MX262 | I26: ATSA | J26: MPC | K26: 337.3 | L26: MXN | M26: Manprec | N26: MAN01013 | O26: FALSE | Q26: EN ALMACEN 11 | S26: FALSE | U26: FALSE
C27: CABLE TRONCAL MONITOR PHILIPS TECNOLOGIA LOGICAL | D27: 0 | E27: PZ | H27: BC-HP-MX1 | I27: ATSA | J27: MPC | K27: 1014.3 | L27: MXN | M27: Manprec | N27: MAN01013 | O27: FALSE | Q27: EN ALMACEN 11 | S27: FALSE | U27: FALSE
C28: KIT DE MONITOREO LOGICAL DESECHABLE | D28: 0 | E28: PZ | H28: MX9604A | I28: ATSA | J28: MPC | K28: 363.8 | L28: MXN | M28: Manprec | N28: MAN01013 | O28: FALSE | Q28: EN ALMACEN 11 | S28: FALSE | U28: FALSE
C29: Brazo de soporte giratorio TPX | D29: 0 | E29: PZ | H29: WP010-MX | I29: TPX | J29: MPC | K29: 115 | L29: USD | M29: MPC | N29: MPC04399 | O29: FALSE | Q29: PENDIENTE | R29: N/A | S29: TRUE | T29: N/A | U29: TRUE
A30: MPC27819 | B30: 3 | C30: Monitor IntelliVue MX450 | D30: 1 | E30: PZ | H30: 866062.2 | I30: PHILIPS | J30: MPC | K30: 2366.75 | L30: USD | M30: N/A | N30: MPC04368 | O30: FALSE | Q30: EN ALMACEN 11 | S30: FALSE | U30: FALSE
A31: MPC27819 | B31: 3.1 | C31: Módulo IntelliVue MMX | D31: 1 | E31: PZ | H31: 867036.1 | I31: PHILIPS | J31: MPC | K31: 1167.58 | L31: USD | M31: N/A | N31: MPC04368 | O31: FALSE | Q31: EN ALMACEN 11 | S31: FALSE | U31: FALSE
C32: CBL 5 Lead ECG Trunk AAMI/IEC 2.7m | D32: 4 | E32: PZ | H32: M1668A | I32: PHILIPS | J32: MPC | K32: 64.23 | L32: USD | M32: N/A | N32: MPC04368 | O32: FALSE | Q32: EN ALMACEN 11 | S32: FALSE | U32: FALSE
C33: CBL 5 Leadset Snap AAMI ICU | D33: 4 | E33: PZ | H33: M1644A | I33: PHILIPS | J33: MPC | K33: 61.51 | L33: USD | M33: N/A | N33: MPC04368 | O33: FALSE | Q33: EN ALMACEN 11 | S33: FALSE | U33: FALSE
C34: CBL 3 Lead ECG Trunk AAMI/IEC 2.7m | D34: 2 | E34: PZ | H34: M1669A | I34: PHILIPS | J34: MPC | K34: 50.08 | L34: USD | M34: N/A | N34: MPC04368 | O34: FALSE | Q34: EN ALMACEN 11 | S34: FALSE | U34: FALSE
C35: CBL 3 Leadset Snap AAMI ICU | D35: 2 | E35: PZ | H35: M1673A | I35: PHILIPS | J35: MPC | K35: 41.91 | L35: USD | M35: N/A | N35: MPC04368 | O35: FALSE | Q35: EN ALMACEN 11 | S35: FALSE | U35: FALSE
C36: Easy Care Cuff 1 Hose Adult (1) | D36: 5 | E36: PZ | H36: M4555B | I36: PHILIPS | J36: MPC | K36: 10.29 | L36: USD | M36: N/A | N36: MPC04368 | O36: FALSE | Q36: EN ALMACEN 11 | S36: FALSE | U36: FALSE
C37: Adult NIBP Air Hose 3.0m | D37: 1 | E37: PZ | H37: 989803209771 | I37: PHILIPS | J37: MPC | K37: 22.37 | L37: USD | M37: N/A | N37: MPC04368 | O37: FALSE | Q37: EN ALMACEN 11 | S37: FALSE | U37: FALSE
C38: SPO2 Reus Ped-Adult Glove Sensor M1192A | D38: 2 | E38: PZ | H38: 989803205871 | I38: PHILIPS | J38: MPC | K38: 92.54 | L38: USD | M38: N/A | N38: MPC04368 | O38: FALSE | Q38: EN ALMACEN 11 | S38: FALSE | U38: FALSE
C39: SPO2 Reus Neo Hnd-Ft Wrap Sensor M1193A | D39: 2 | E39: PZ | H39: 989803205881 | I39: PHILIPS | J39: MPC | K39: 91.99 | L39: USD | M39: N/A | N39: MPC04368 | O39: FALSE | Q39: EN ALMACEN 11 | S39: FALSE | U39: FALSE
